<?xml version="1.0"?>
<robot name="stanford_hopper_simple">

  <link name="base_link">
    <visual>
      <geometry>
        <box size="0.108 0.1 0.07"/>
      </geometry>
      <origin xyz="0 0 0"/>
      <material name="blue">
        <color rgba="0 0 .8 1"/>
      </material>
    </visual>
    <collision>
      <geometry>
          <box size="0.108 0.1 0.1"/>
      </geometry>
      <origin xyz="0 0 0"/>
    </collision>
    <inertial>
      <mass value="0.0"/>
      <inertia ixx="1.0" ixy="0.0" ixz="0.0" iyy="1.0" iyz="0.0" izz="1.0"/>
    </inertial>
  </link>

  <link name="leg_left">
    <visual>
      <geometry>
       <box size="0.03 0.01 0.05"/>	
      </geometry>
      <origin rpy="0 0 0" xyz="0 0 0.5"/>
      <material name="white">
        <color rgba="1 1 1 1"/>
      </material>
    </visual>
    <inertial>
    <origin xyz="0 0 0"/>
      <mass value="0.1"/>
      <inertia ixx="1.0" ixy="0.0" ixz="0.0" iyy="1.0" iyz="0.0" izz="1.0"/>
    </inertial>
    <collision>
      <geometry>
        <box size="0.03 0.01 0.05"/>	
      </geometry>
      <origin rpy="0 0 0" xyz="0 0 0"/>
    </collision>
  </link>

  <joint name="base_link_to_leg_left" type="fixed">
    <axis xyz="0 1 0"/>
    <origin xyz="0.0 0.04 -0.56"/>
    <limit effort="0.1" lower="-0.0000001" upper="0.0000001" velocity="0.0005"/>
    <parent link="base_link"/>
    <child link="leg_left"/>
  </joint>

  <link name="leg_right">
    <visual>
      <geometry>
       <box size="0.03 0.01 0.05"/>	
      </geometry>
      <origin rpy="0 0 0" xyz="0 0 0.5"/>
      <material name="white">
        <color rgba="1 1 1 1"/>
      </material>
    </visual>
    <inertial>
    <origin xyz="0 0 0"/>
      <mass value="0.1"/>
      <inertia ixx="1.0" ixy="0.0" ixz="0.0" iyy="1.0" iyz="0.0" izz="1.0"/>
    </inertial>
    <collision>
      <geometry>
        <box size="0.03 0.01 0.05"/>	
      </geometry>
      <origin rpy="0 0 0" xyz="0 0 0"/>
    </collision>
  </link>

  <joint name="base_link_to_leg_right" type="fixed">
    <axis xyz="0 1 0"/>
    <origin xyz="0.0 -0.04 -0.56"/>
    <limit effort="0.1" lower="-0.0000001" upper="0.0000001" velocity="0.0005"/>
    <parent link="base_link"/>
    <child link="leg_right"/>
  </joint>


  <link name="slide_left">
    <visual>
      <geometry>
       <box size="0.02 0.01 0.075"/>	
      </geometry>
      <origin rpy="0 0 0" xyz="0 0 0.5"/>
      <material name="white">
        <color rgba="1 1 1 1"/>
      </material>
    </visual>
    <inertial>
    <origin xyz="0 0 0"/>
      <mass value="0.1"/>
      <inertia ixx="1.0" ixy="0.0" ixz="0.0" iyy="1.0" iyz="0.0" izz="1.0"/>
    </inertial>
    <collision>
      <geometry>
        <box size="0.02 0.01 0.1"/>	
      </geometry>
      <origin rpy="0 0 0" xyz="0 0 0"/>
    </collision>
  </link>

  <joint name="left_extend" type="prismatic">
    <axis xyz="0 0 1"/>
    <parent link="leg_left"/>
    <child link="slide_left"/>
    <limit effort="0.1" lower="-0.06" upper="0.01" velocity="0.0005"/>
    <origin rpy="0 0 0" xyz="0 0 0"/>
  </joint>

  <link name="slide_right">
    <visual>
      <geometry>
       <box size="0.02 0.01 0.075"/>	
      </geometry>
      <origin rpy="0 0 0" xyz="0 0 0.5"/>
      <material name="white">
        <color rgba="1 1 1 1"/>
      </material>
    </visual>
    <inertial>
    <origin xyz="0 0 0"/>
      <mass value="0.1"/>
      <inertia ixx="1.0" ixy="0.0" ixz="0.0" iyy="1.0" iyz="0.0" izz="1.0"/>
    </inertial>
    <collision>
      <geometry>
        <box size="0.02 0.01 0.1"/>	
      </geometry>
      <origin rpy="0 0 0" xyz="0 0 0"/>
    </collision>
  </link>

  <joint name="right_extend" type="prismatic">
    <axis xyz="0 0 1"/>
    <parent link="leg_right"/>
    <child link="slide_right"/>
    <limit effort="0.1" lower="-0.06" upper="0.01" velocity="0.0005"/>
    <origin rpy="0 0 0" xyz="0 0 0"/>
  </joint>

  <link name="wheel_left">
    <visual>
      <geometry>
       <cylinder radius="0.0152" length="0.01"/>	
      </geometry>
      <origin rpy="0 0 0" xyz="0 0 0.5"/>
      <material name="blue">
        <color rgba="1 1 1 1"/>
      </material>
    </visual>
    <inertial>
    <origin xyz="0 0 0"/>
      <mass value="0.1"/>
      <inertia ixx="1.0" ixy="0.0" ixz="0.0" iyy="1.0" iyz="0.0" izz="1.0"/>
    </inertial>
    <collision>
      <geometry>
       <cylinder radius="0.0152" length="0.01"/>	
      </geometry>
      <origin rpy="0 0 0" xyz="0 0 0.5"/>
    </collision>
  </link>

  <joint name="wheel_left_joint" type="continuous">
    <axis xyz="0 0 1"/>
    <parent link="slide_left"/>
    <child link="wheel_left"/>
    <limit effort="0.05" velocity="0.001"/>
    <origin rpy="1.57075 0 0" xyz="0 0.51 0.47"/>
  </joint>

  <link name="wheel_right">
    <visual>
      <geometry>
       <cylinder radius="0.0152" length="0.01"/>	
      </geometry>
      <origin rpy="0 0 0" xyz="0 0 0.5"/>
      <material name="blue">
        <color rgba="1 1 1 1"/>
      </material>
    </visual>
    <inertial>
    <origin xyz="0 0 0"/>
      <mass value="0.1"/>
      <inertia ixx="1.0" ixy="0.0" ixz="0.0" iyy="1.0" iyz="0.0" izz="1.0"/>
    </inertial>
    <collision>
      <geometry>
       <cylinder radius="0.0152" length="0.01"/>	
      </geometry>
      <origin rpy="0 0 0" xyz="0 0 0.5"/>
    </collision>
  </link>

  <joint name="wheel_right_joint" type="continuous">
    <axis xyz="0 0 1"/>
    <parent link="slide_right"/>
    <child link="wheel_right"/>
    <limit effort="0.05" velocity="0.001"/>
    <origin rpy="-1.57075 0 0" xyz="0 -0.51 0.47"/>
  </joint>

</robot>